Workbook
Name Segment_An: #N/A
Name Segment_An1: #N/A
Name Segment_An2: #N/A
Name Segment_Mois: #N/A
Name Segment_Mois1: #N/A
Name Segment_Mois2: #N/A
Name Segment_Mois3: #N/A

Sheet Feuil2
A1: Date | B1: Section | C1: Type d'intervention | D1: Machine | E1: Code | F1: Partie Machine | G1: Intervention | H1: TA (min) | I1: Résultat
A2: 43496 | B2: =IF(ISNA(VLOOKUP(Tableau1[[#This Row],[Code]],'Code Véhicule'!$A$4:$C$85,2,FALSE))," ",VLOOKUP(Tableau1[[#This Row],[Code]],'Code Véhicule'!$A$4:$C$85,2,FALSE)) | C2: Réglage | D2: =IF(ISNA(VLOOKUP(Tableau1[[#This Row],[Code]],'Code Véhicule'!$A$4:$C$85,3,FALSE))," ",VLOOKUP(Tableau1[[#This Row],[Code]],'Code Véhicule'!$A$4:$C$85,3,FALSE)) | E2: 560 | F2: Cisaille | G2: Réglage de la pression de l'air pour l'ajustement des cames de la cisaille | I2: Came ajustée Machine opérationelle
A3: 43496 | B3: =IF(ISNA(VLOOKUP(Tableau1[[#This Row],[Code]],'Code Véhicule'!$A$4:$C$85,2,FALSE))," ",VLOOKUP(Tableau1[[#This Row],[Code]],'Code Véhicule'!$A$4:$C$85,2,FALSE)) | C3: Réparation | D3: =IF(ISNA(VLOOKUP(Tableau1[[#This Row],[Code]],'Code Véhicule'!$A$4:$C$85,3,FALSE))," ",VLOOKUP(Tableau1[[#This Row],[Code]],'Code Véhicule'!$A$4:$C$85,3,FALSE)) | E3: 582 | F3: Cassette PR 3,20 | G3: Nettoyage, démontage de la cassette 3,20 - changement des roulement endommagés | I3: Cassette opérationnelle
A4: 43496 | B4: =IF(ISNA(VLOOKUP(Tableau1[[#This Row],[Code]],'Code Véhicule'!$A$4:$C$85,2,FALSE))," ",VLOOKUP(Tableau1[[#This Row],[Code]],'Code Véhicule'!$A$4:$C$85,2,FALSE)) | C4: Contrôle | D4: =IF(ISNA(VLOOKUP(Tableau1[[#This Row],[Code]],'Code Véhicule'!$A$4:$C$85,3,FALSE))," ",VLOOKUP(Tableau1[[#This Row],[Code]],'Code Véhicule'!$A$4:$C$85,3,FALSE)) | E4: 800 | F4: Groupe hydraulique | G4: Rajout d'huile hydraulique | I4: Niveau d'huile corrigé
A5: 43496 | B5: =IF(ISNA(VLOOKUP(Tableau1[[#This Row],[Code]],'Code Véhicule'!$A$4:$C$85,2,FALSE))," ",VLOOKUP(Tableau1[[#This Row],[Code]],'Code Véhicule'!$A$4:$C$85,2,FALSE)) | C5: Réparation | D5: =IF(ISNA(VLOOKUP(Tableau1[[#This Row],[Code]],'Code Véhicule'!$A$4:$C$85,3,FALSE))," ",VLOOKUP(Tableau1[[#This Row],[Code]],'Code Véhicule'!$A$4:$C$85,3,FALSE)) | E5: 700 | F5: Eclairage | G5: Détection du court circuit au niveau du circuit d'alimentation des ampoules se situant au dessus du malaxeur, changement des fils endommagé. | I5: Eclairage en bon état
A6: 43496 | B6: =IF(ISNA(VLOOKUP(Tableau1[[#This Row],[Code]],'Code Véhicule'!$A$4:$C$85,2,FALSE))," ",VLOOKUP(Tableau1[[#This Row],[Code]],'Code Véhicule'!$A$4:$C$85,2,FALSE)) | C6: Confection | D6: =IF(ISNA(VLOOKUP(Tableau1[[#This Row],[Code]],'Code Véhicule'!$A$4:$C$85,3,FALSE))," ",VLOOKUP(Tableau1[[#This Row],[Code]],'Code Véhicule'!$A$4:$C$85,3,FALSE)) | E6: 565 | F6: Electrodes | G6: Découpe +perçage des électrode en cuivre | I6: Préparation de 14 électrodes en cuivre prêtes à l'emploi
A7: 43496 | B7: =IF(ISNA(VLOOKUP(Tableau1[[#This Row],[Code]],'Code Véhicule'!$A$4:$C$85,2,FALSE))," ",VLOOKUP(Tableau1[[#This Row],[Code]],'Code Véhicule'!$A$4:$C$85,2,FALSE)) | C7: Vidange | D7: =IF(ISNA(VLOOKUP(Tableau1[[#This Row],[Code]],'Code Véhicule'!$A$4:$C$85,3,FALSE))," ",VLOOKUP(Tableau1[[#This Row],[Code]],'Code Véhicule'!$A$4:$C$85,3,FALSE)) | E7: 533 | F7: Mélangeur | G7: Vidange du réducteur du mélangeur | I7: Réducteur vidangé
A8: 43496 | B8: Gestion de stock | C8: Contrôle | D8: Grue à tour | F8: Treuil principal | G8: Diagnostic : Mesure d'isolement +mesure de continuité du motofrein montée descente | I8: Enroulement de la bobine du frein coupé - Démontage prévu: 01/02/2019 + Transmission vers CEDP pour réparation
A9: 43497 | B9: =IF(ISNA(VLOOKUP(Tableau1[[#This Row],[Code]],'Code Véhicule'!$A$4:$C$85,2,FALSE))," ",VLOOKUP(Tableau1[[#This Row],[Code]],'Code Véhicule'!$A$4:$C$85,2,FALSE)) | C9: Réparation | D9: =IF(ISNA(VLOOKUP(Tableau1[[#This Row],[Code]],'Code Véhicule'!$A$4:$C$85,3,FALSE))," ",VLOOKUP(Tableau1[[#This Row],[Code]],'Code Véhicule'!$A$4:$C$85,3,FALSE)) | E9: 571 | F9: Cisaille | G9: Elimination d'une fuite d'huile au niveau de la cisaille : changement d'un flexible hydraulique | I9: Fuite éliminée
A10: 43497 | B10: =IF(ISNA(VLOOKUP(Tableau1[[#This Row],[Code]],'Code Véhicule'!$A$4:$C$85,2,FALSE))," ",VLOOKUP(Tableau1[[#This Row],[Code]],'Code Véhicule'!$A$4:$C$85,2,FALSE)) | C10: Confection | D10: =IF(ISNA(VLOOKUP(Tableau1[[#This Row],[Code]],'Code Véhicule'!$A$4:$C$85,3,FALSE))," ",VLOOKUP(Tableau1[[#This Row],[Code]],'Code Véhicule'!$A$4:$C$85,3,FALSE)) | E10: 571 | F10: Electrodes | G10: Découpe + surfaçage des électrodes en cuivre | I10: Préparation de 20 éléctrodes en cuivres
A11: 43497 | B11: =IF(ISNA(VLOOKUP(Tableau1[[#This Row],[Code]],'Code Véhicule'!$A$4:$C$85,2,FALSE))," ",VLOOKUP(Tableau1[[#This Row],[Code]],'Code Véhicule'!$A$4:$C$85,2,FALSE)) | C11: Réparation | D11: =IF(ISNA(VLOOKUP(Tableau1[[#This Row],[Code]],'Code Véhicule'!$A$4:$C$85,3,FALSE))," ",VLOOKUP(Tableau1[[#This Row],[Code]],'Code Véhicule'!$A$4:$C$85,3,FALSE)) | E11: 700 | F11: Moule | G11: Changement du vérin du moule ( le premier avait une fuite au niveau du raccord) | I11: Fuite éliminée Vérin monté
A12: 43497 | B12: =IF(ISNA(VLOOKUP(Tableau1[[#This Row],[Code]],'Code Véhicule'!$A$4:$C$85,2,FALSE))," ",VLOOKUP(Tableau1[[#This Row],[Code]],'Code Véhicule'!$A$4:$C$85,2,FALSE)) | C12: Contrôle | D12: =IF(ISNA(VLOOKUP(Tableau1[[#This Row],[Code]],'Code Véhicule'!$A$4:$C$85,3,FALSE))," ",VLOOKUP(Tableau1[[#This Row],[Code]],'Code Véhicule'!$A$4:$C$85,3,FALSE)) | E12: 800 | F12: Descenseur | G12: Tension des chaines du descenseur | I12: Chaines tendue
A13: 43497 | B13: =IF(ISNA(VLOOKUP(Tableau1[[#This Row],[Code]],'Code Véhicule'!$A$4:$C$85,2,FALSE))," ",VLOOKUP(Tableau1[[#This Row],[Code]],'Code Véhicule'!$A$4:$C$85,2,FALSE)) | C13: Contrôle | D13: =IF(ISNA(VLOOKUP(Tableau1[[#This Row],[Code]],'Code Véhicule'!$A$4:$C$85,3,FALSE))," ",VLOOKUP(Tableau1[[#This Row],[Code]],'Code Véhicule'!$A$4:$C$85,3,FALSE)) | E13: 800 | F13: Cercleuse | G13: Soufflage des cercleuses et nettoyage de la tete chauffante | I13: Cercleuse opérationnelle
A14: 43497 | B14: =IF(ISNA(VLOOKUP(Tableau1[[#This Row],[Code]],'Code Véhicule'!$A$4:$C$85,2,FALSE))," ",VLOOKUP(Tableau1[[#This Row],[Code]],'Code Véhicule'!$A$4:$C$85,2,FALSE)) | C14: Réparation | D14: =IF(ISNA(VLOOKUP(Tableau1[[#This Row],[Code]],'Code Véhicule'!$A$4:$C$85,3,FALSE))," ",VLOOKUP(Tableau1[[#This Row],[Code]],'Code Véhicule'!$A$4:$C$85,3,FALSE)) | E14: 562 | F14: Alimentation générale | G14: Réarmement du disjoncteur général ( le disjoncteur est tombé à cause d'une collision entre deux ponts roulants) | I14: Disjoncteur réarmé - pont roulant opérationnel
A15: 43497 | B15: =IF(ISNA(VLOOKUP(Tableau1[[#This Row],[Code]],'Code Véhicule'!$A$4:$C$85,2,FALSE))," ",VLOOKUP(Tableau1[[#This Row],[Code]],'Code Véhicule'!$A$4:$C$85,2,FALSE)) | C15: Réparation | D15: =IF(ISNA(VLOOKUP(Tableau1[[#This Row],[Code]],'Code Véhicule'!$A$4:$C$85,3,FALSE))," ",VLOOKUP(Tableau1[[#This Row],[Code]],'Code Véhicule'!$A$4:$C$85,3,FALSE)) | E15: 565 | F15: Circuit de refroidissement | G15: Changement d'un flexible de refroidissement | I15: Circuit de refroidissement en bon état
A16: 43497 | B16: Usine | C16: Vidange | D16: Fosse séptique | G16: Vidange de la fosse séptique | I16: Fosse séptique vidangée La taille de la fosse est très petite environ 10 metre cube
A17: 43500 | B17: =IF(ISNA(VLOOKUP(Tableau1[[#This Row],[Code]],'Code Véhicule'!$A$4:$C$85,2,FALSE))," ",VLOOKUP(Tableau1[[#This Row],[Code]],'Code Véhicule'!$A$4:$C$85,2,FALSE)) | C17: Réparation | D17: =IF(ISNA(VLOOKUP(Tableau1[[#This Row],[Code]],'Code Véhicule'!$A$4:$C$85,3,FALSE))," ",VLOOKUP(Tableau1[[#This Row],[Code]],'Code Véhicule'!$A$4:$C$85,3,FALSE)) | E17: 800 | F17: Silo à ciment | G17: Montage des pièces du réducteur des vis à ciment | I17: Réducteur opérationel prêt à l'emploie
A18: 43500 | B18: Gestion de stock | C18: Démontage | D18: Grue à tour | F18: Treuil principal | G18: Démontage du frein endommagé de la grue à tour | I18: Attente CEDP pour réparation
A19: 43500 | B19: =IF(ISNA(VLOOKUP(Tableau1[[#This Row],[Code]],'Code Véhicule'!$A$4:$C$85,2,FALSE))," ",VLOOKUP(Tableau1[[#This Row],[Code]],'Code Véhicule'!$A$4:$C$85,2,FALSE)) | C19: Réparation | D19: =IF(ISNA(VLOOKUP(Tableau1[[#This Row],[Code]],'Code Véhicule'!$A$4:$C$85,3,FALSE))," ",VLOOKUP(Tableau1[[#This Row],[Code]],'Code Véhicule'!$A$4:$C$85,3,FALSE)) | E19: 581 | F19: Cassette PR 8 | G19: Changement de 6 roulement 32008 partie crantée + Zoomage | I19: Cassette opérationelle
A20: 43500 | B20: =IF(ISNA(VLOOKUP(Tableau1[[#This Row],[Code]],'Code Véhicule'!$A$4:$C$85,2,FALSE))," ",VLOOKUP(Tableau1[[#This Row],[Code]],'Code Véhicule'!$A$4:$C$85,2,FALSE)) | C20: Réparation | D20: =IF(ISNA(VLOOKUP(Tableau1[[#This Row],[Code]],'Code Véhicule'!$A$4:$C$85,3,FALSE))," ",VLOOKUP(Tableau1[[#This Row],[Code]],'Code Véhicule'!$A$4:$C$85,3,FALSE)) | E20: 580 | F20: Bobinoir | G20: Changement des boulons de fixation du bobinoir ( boulons endomagés)
A21: 43500 | B21: =IF(ISNA(VLOOKUP(Tableau1[[#This Row],[Code]],'Code Véhicule'!$A$4:$C$85,2,FALSE))," ",VLOOKUP(Tableau1[[#This Row],[Code]],'Code Véhicule'!$A$4:$C$85,2,FALSE)) | C21: Contrôle | D21: =IF(ISNA(VLOOKUP(Tableau1[[#This Row],[Code]],'Code Véhicule'!$A$4:$C$85,3,FALSE))," ",VLOOKUP(Tableau1[[#This Row],[Code]],'Code Véhicule'!$A$4:$C$85,3,FALSE)) | E21: 533 | F21: Mélangeur | G21: Elimination d'une fuite au niveau du réducteur du mélangeur | I21: Fuite éliminée -Bruit anormal au niveau du réducteur Prévoir un arrêt pour vérification du réducteur
A22: 43500 | B22: =IF(ISNA(VLOOKUP(Tableau1[[#This Row],[Code]],'Code Véhicule'!$A$4:$C$85,2,FALSE))," ",VLOOKUP(Tableau1[[#This Row],[Code]],'Code Véhicule'!$A$4:$C$85,2,FALSE)) | C22: Réglage | D22: =IF(ISNA(VLOOKUP(Tableau1[[#This Row],[Code]],'Code Véhicule'!$A$4:$C$85,3,FALSE))," ",VLOOKUP(Tableau1[[#This Row],[Code]],'Code Véhicule'!$A$4:$C$85,3,FALSE)) | E22: 607 | F22: Devidoir | G22: Réglage du potentiométre du devidoir + changement des silents blocs du danseur | I22: Machine opérationelle
A23: 43500 | B23: =IF(ISNA(VLOOKUP(Tableau1[[#This Row],[Code]],'Code Véhicule'!$A$4:$C$85,2,FALSE))," ",VLOOKUP(Tableau1[[#This Row],[Code]],'Code Véhicule'!$A$4:$C$85,2,FALSE)) | C23: Réglage | D23: =IF(ISNA(VLOOKUP(Tableau1[[#This Row],[Code]],'Code Véhicule'!$A$4:$C$85,3,FALSE))," ",VLOOKUP(Tableau1[[#This Row],[Code]],'Code Véhicule'!$A$4:$C$85,3,FALSE)) | E23: 605 | F23: Guide fil | G23: Dressage des barres du guides fils | I23: Machine opérationelle
A24: 43500 | B24: =IF(ISNA(VLOOKUP(Tableau1[[#This Row],[Code]],'Code Véhicule'!$A$4:$C$85,2,FALSE))," ",VLOOKUP(Tableau1[[#This Row],[Code]],'Code Véhicule'!$A$4:$C$85,2,FALSE)) | C24: Réparation | D24: =IF(ISNA(VLOOKUP(Tableau1[[#This Row],[Code]],'Code Véhicule'!$A$4:$C$85,3,FALSE))," ",VLOOKUP(Tableau1[[#This Row],[Code]],'Code Véhicule'!$A$4:$C$85,3,FALSE)) | E24: 568 | F24: Moteur de levage | G24: Montage du frein (Monté-Descente) | I24: Pont roulant opérationel
A25: 43501 | B25: =IF(ISNA(VLOOKUP(Tableau1[[#This Row],[Code]],'Code Véhicule'!$A$4:$C$85,2,FALSE))," ",VLOOKUP(Tableau1[[#This Row],[Code]],'Code Véhicule'!$A$4:$C$85,2,FALSE)) | C25: Confection | D25: =IF(ISNA(VLOOKUP(Tableau1[[#This Row],[Code]],'Code Véhicule'!$A$4:$C$85,3,FALSE))," ",VLOOKUP(Tableau1[[#This Row],[Code]],'Code Véhicule'!$A$4:$C$85,3,FALSE)) | E25: 571 | F25: Electrodes | G25: Découpe électrodes en cuivre | I25: 10 électrodes prêtes pour le surfaçage
A26: 43501 | B26: =IF(ISNA(VLOOKUP(Tableau1[[#This Row],[Code]],'Code Véhicule'!$A$4:$C$85,2,FALSE))," ",VLOOKUP(Tableau1[[#This Row],[Code]],'Code Véhicule'!$A$4:$C$85,2,FALSE)) | C26: Réparation | D26: =IF(ISNA(VLOOKUP(Tableau1[[#This Row],[Code]],'Code Véhicule'!$A$4:$C$85,3,FALSE))," ",VLOOKUP(Tableau1[[#This Row],[Code]],'Code Véhicule'!$A$4:$C$85,3,FALSE)) | E26: 560 | F26: Circuit de refroidissement | G26: Changement d'un flexible de refroidissement | I26: RAS
A27: 43501 | B27: =IF(ISNA(VLOOKUP(Tableau1[[#This Row],[Code]],'Code Véhicule'!$A$4:$C$85,2,FALSE))," ",VLOOKUP(Tableau1[[#This Row],[Code]],'Code Véhicule'!$A$4:$C$85,2,FALSE)) | C27: Réparation | D27: =IF(ISNA(VLOOKUP(Tableau1[[#This Row],[Code]],'Code Véhicule'!$A$4:$C$85,3,FALSE))," ",VLOOKUP(Tableau1[[#This Row],[Code]],'Code Véhicule'!$A$4:$C$85,3,FALSE)) | E27: 700 | F27: Moule | G27: Changement des nécessaires du vérin du moule | I27: Vérin prêt à l'emploi
A28: 43501 | B28: =IF(ISNA(VLOOKUP(Tableau1[[#This Row],[Code]],'Code Véhicule'!$A$4:$C$85,2,FALSE))," ",VLOOKUP(Tableau1[[#This Row],[Code]],'Code Véhicule'!$A$4:$C$85,2,FALSE)) | C28: Réparation | D28: =IF(ISNA(VLOOKUP(Tableau1[[#This Row],[Code]],'Code Véhicule'!$A$4:$C$85,3,FALSE))," ",VLOOKUP(Tableau1[[#This Row],[Code]],'Code Véhicule'!$A$4:$C$85,3,FALSE)) | E28: 562 | F28: Alimentation générale | G28: Réparation du circuit électrique de commande | I28: Pont roulant opérationel
A29: 43501 | B29: =IF(ISNA(VLOOKUP(Tableau1[[#This Row],[Code]],'Code Véhicule'!$A$4:$C$85,2,FALSE))," ",VLOOKUP(Tableau1[[#This Row],[Code]],'Code Véhicule'!$A$4:$C$85,2,FALSE)) | C29: Réparation | D29: =IF(ISNA(VLOOKUP(Tableau1[[#This Row],[Code]],'Code Véhicule'!$A$4:$C$85,3,FALSE))," ",VLOOKUP(Tableau1[[#This Row],[Code]],'Code Véhicule'!$A$4:$C$85,3,FALSE)) | E29: 580 | F29: Circuit de refroidissement | G29: Débouchage du circuit de refroidissement du cabestan | I29: Intervention d'un plombier nécessaire (prévu le 07/02/2019)
A30: 43501 | B30: =IF(ISNA(VLOOKUP(Tableau1[[#This Row],[Code]],'Code Véhicule'!$A$4:$C$85,2,FALSE))," ",VLOOKUP(Tableau1[[#This Row],[Code]],'Code Véhicule'!$A$4:$C$85,2,FALSE)) | C30: Réparation | D30: =IF(ISNA(VLOOKUP(Tableau1[[#This Row],[Code]],'Code Véhicule'!$A$4:$C$85,3,FALSE))," ",VLOOKUP(Tableau1[[#This Row],[Code]],'Code Véhicule'!$A$4:$C$85,3,FALSE)) | E30: 581 | F30: Cassette PR 8 | G30: Débouchage du circtuit de refroidissement de la cassette PR8 | I30: Cassette opérationnelle
A31: 43501 | B31: Usine | C31: Rénnovation | D31: =IF(ISNA(VLOOKUP(Tableau1[[#This Row],[Code]],'Code Véhicule'!$A$4:$C$85,3,FALSE))," ",VLOOKUP(Tableau1[[#This Row],[Code]],'Code Véhicule'!$A$4:$C$85,3,FALSE)) | G31: Début des travaux de changement des plaques translucides | I31: Travaux en cours
A32: 43502 | B32: =IF(ISNA(VLOOKUP(Tableau1[[#This Row],[Code]],'Code Véhicule'!$A$4:$C$85,2,FALSE))," ",VLOOKUP(Tableau1[[#This Row],[Code]],'Code Véhicule'!$A$4:$C$85,2,FALSE)) | C32: Réparation | D32: =IF(ISNA(VLOOKUP(Tableau1[[#This Row],[Code]],'Code Véhicule'!$A$4:$C$85,3,FALSE))," ",VLOOKUP(Tableau1[[#This Row],[Code]],'Code Véhicule'!$A$4:$C$85,3,FALSE)) | E32: 605 | F32: Vibreur | G32: Extraction d'une vis + taraudage du support du vibreur | I32: Machine opérationelle
A33: 43502 | B33: =IF(ISNA(VLOOKUP(Tableau1[[#This Row],[Code]],'Code Véhicule'!$A$4:$C$85,2,FALSE))," ",VLOOKUP(Tableau1[[#This Row],[Code]],'Code Véhicule'!$A$4:$C$85,2,FALSE)) | C33: Réparation | D33: =IF(ISNA(VLOOKUP(Tableau1[[#This Row],[Code]],'Code Véhicule'!$A$4:$C$85,3,FALSE))," ",VLOOKUP(Tableau1[[#This Row],[Code]],'Code Véhicule'!$A$4:$C$85,3,FALSE)) | E33: 565 | F33: Table élévatrice | G33: Changement d'un pignon tendeur de la chaine de la table élévatrice | I33: Machine opérationelle
A34: 43502 | B34: =IF(ISNA(VLOOKUP(Tableau1[[#This Row],[Code]],'Code Véhicule'!$A$4:$C$85,2,FALSE))," ",VLOOKUP(Tableau1[[#This Row],[Code]],'Code Véhicule'!$A$4:$C$85,2,FALSE)) | C34: Réparation | D34: =IF(ISNA(VLOOKUP(Tableau1[[#This Row],[Code]],'Code Véhicule'!$A$4:$C$85,3,FALSE))," ",VLOOKUP(Tableau1[[#This Row],[Code]],'Code Véhicule'!$A$4:$C$85,3,FALSE)) | E34: 581 | F34: Cassette PR 10 | G34: Changement de 6 roulement partie crantée de la cassette PR10 | I34: Cassette opérationnelle
A35: 43502 | B35: =IF(ISNA(VLOOKUP(Tableau1[[#This Row],[Code]],'Code Véhicule'!$A$4:$C$85,2,FALSE))," ",VLOOKUP(Tableau1[[#This Row],[Code]],'Code Véhicule'!$A$4:$C$85,2,FALSE)) | C35: Réparation | D35: =IF(ISNA(VLOOKUP(Tableau1[[#This Row],[Code]],'Code Véhicule'!$A$4:$C$85,3,FALSE))," ",VLOOKUP(Tableau1[[#This Row],[Code]],'Code Véhicule'!$A$4:$C$85,3,FALSE)) | E35: 533 | F35: Mélangeur | G35: Changement des roulements du réducteur du mélangeur + Changement des roulement du support de pales + Vidange du réducteur | I35: Travaux en cours - Disponibilité de la machine prévu le 07/02/2019 à 10H
A36: 43502 | B36: =IF(ISNA(VLOOKUP(Tableau1[[#This Row],[Code]],'Code Véhicule'!$A$4:$C$85,2,FALSE))," ",VLOOKUP(Tableau1[[#This Row],[Code]],'Code Véhicule'!$A$4:$C$85,2,FALSE)) | C36: Réparation | D36: =IF(ISNA(VLOOKUP(Tableau1[[#This Row],[Code]],'Code Véhicule'!$A$4:$C$85,3,FALSE))," ",VLOOKUP(Tableau1[[#This Row],[Code]],'Code Véhicule'!$A$4:$C$85,3,FALSE)) | E36: 560 | F36: Bloc de soudure | G36: Perçage + taraudage du support de fixation des électrodes du sabot de soudage | I36: Sabot opérationnel
A37: 43502 | B37: =IF(ISNA(VLOOKUP(Tableau1[[#This Row],[Code]],'Code Véhicule'!$A$4:$C$85,2,FALSE))," ",VLOOKUP(Tableau1[[#This Row],[Code]],'Code Véhicule'!$A$4:$C$85,2,FALSE)) | C37: Changement | D37: =IF(ISNA(VLOOKUP(Tableau1[[#This Row],[Code]],'Code Véhicule'!$A$4:$C$85,3,FALSE))," ",VLOOKUP(Tableau1[[#This Row],[Code]],'Code Véhicule'!$A$4:$C$85,3,FALSE)) | E37: 560 | F37: Circuit de refroidissement | G37: Changement d'un flexible de refroidissement endommagé | I37: Circuit RAS
A38: 43502 | B38: =IF(ISNA(VLOOKUP(Tableau1[[#This Row],[Code]],'Code Véhicule'!$A$4:$C$85,2,FALSE))," ",VLOOKUP(Tableau1[[#This Row],[Code]],'Code Véhicule'!$A$4:$C$85,2,FALSE)) | C38: Réparation | D38: =IF(ISNA(VLOOKUP(Tableau1[[#This Row],[Code]],'Code Véhicule'!$A$4:$C$85,3,FALSE))," ",VLOOKUP(Tableau1[[#This Row],[Code]],'Code Véhicule'!$A$4:$C$85,3,FALSE)) | E38: 800 | F38: Pilon | G38: Changement de l'axe de fixation du vérin du pilon | I38: Machine opérationnelle
A39: 43503 | B39: =IF(ISNA(VLOOKUP(Tableau1[[#This Row],[Code]],'Code Véhicule'!$A$4:$C$85,2,FALSE))," ",VLOOKUP(Tableau1[[#This Row],[Code]],'Code Véhicule'!$A$4:$C$85,2,FALSE)) | C39: Réparation | D39: =IF(ISNA(VLOOKUP(Tableau1[[#This Row],[Code]],'Code Véhicule'!$A$4:$C$85,3,FALSE))," ",VLOOKUP(Tableau1[[#This Row],[Code]],'Code Véhicule'!$A$4:$C$85,3,FALSE)) | E39: 565 | F39: Table élévatrice | G39: Montage de la vis sans fin + l'écrou en bronze de la table élévatrice | I39: Machine opérationnelle
A40: 43503 | B40: =IF(ISNA(VLOOKUP(Tableau1[[#This Row],[Code]],'Code Véhicule'!$A$4:$C$85,2,FALSE))," ",VLOOKUP(Tableau1[[#This Row],[Code]],'Code Véhicule'!$A$4:$C$85,2,FALSE)) | C40: Réparation | D40: =IF(ISNA(VLOOKUP(Tableau1[[#This Row],[Code]],'Code Véhicule'!$A$4:$C$85,3,FALSE))," ",VLOOKUP(Tableau1[[#This Row],[Code]],'Code Véhicule'!$A$4:$C$85,3,FALSE)) | E40: 571 | F40: Cisaille | G40: Perçage + taraudage du support de fixation des distributeurs pneumatiques de la cisaille | I40: Machine OP
...

Sheet Menu

Sheet Code Véhicule
A1: Liste code véhicules
A3: CODE Véhicule | B3: Type | C3: Marque | D3: Matricule
A4: 7 | B4: Voiture de fonction | C4: Berlingo | D4: 50313-A-6
A5: 401 | B5: Camion | C5: ISUZU | D5: 26128-A-8
A6: 403 | B6: Camion | C6: MAN | D6: 4790-B-8
A7: 404 | B7: Semi remorque | C7: VOLVO | D7: 68125-A-6
A8: 405 | B8: Camion | C8: ISUZU | D8: 22128-W-6
A9: 406 | B9: Semi remorque | C9: VOLVO | D9: 70352-A-6
A10: 407 | B10: Semi remorque | C10: MAN | D10: 706-A-73
A11: 408 | B11: Camion | C11: Mitsubishi | D11: 4703-A-73
A12: 409 | B12: Camion | C12: Mitsubishi | D12: 4969-A-73
A13: 410 | B13: Semi remorque | C13: MAN | D13: 28659-D-1
A14: 411 | B14: Camion | C14: Renault | D14: 25636-A-13
A15: 413 | B15: Chargeur | C15: Caterpillar | D15: -
A16: 413B | B16: Chargeur | C16: Caterpillar | D16: -
A17: 414 | B17: Balayeuse | C17: Bobcat | D17: -
A18: 417 | B18: Voiture de fonction | C18: Berlingo | D18: 981-A-73
A19: 419 | B19: Voiture de fonction | C19: kangoo | D19: 4812-A-73
A20: 421 | B20: Chariot elevateur | C20: Linde H30 | D20: -
A21: 422 | B21: Chariot elevateur | C21: Fenwick LINDE 25 | D21: -
A22: 426 | B22: Chariot elevateur | C22: Manitou MC 30 | D22: -
A23: 427 | B23: Chariot elevateur | C23: Linde H30 | D23: -
A24: 428 | B24: Chariot elevateur | C24: Linde H30 | D24: -
A25: 429 | B25: Chariot elevateur | C25: Fenwick HD30 | D25: -
A26: 430 | B26: Chariot elevateur | C26: Fenwick H40 | D26: -
A27: 431 | B27: Chariot elevateur | C27: Manitou M26-2 | D27: -
A28: 432 | B28: Voiture de fonction | C28: Berlingo | D28: 9660 -A-73
... A41: 482 | B41: Pick up | C41: HYUNDAI H100 | D41: 22368-A-73
A42: ARM | B42: Semi remorque | C42: MAN | D42: 28661-D-1
A43: 420 | B43: Chariot elevateur | C43: linde h 45
A44: 483 | B44: Chariot elevateur | C44: MI50D
A45: 484 | B45: Chariot elevateur | C45: MI50D

Sheet Feuil3
Z4: Colonne1 | AA4: Colonne2 | AB4: Colonne3 | AC4: Colonne4 | AD4: Colonne5 | AE4: Colonne6

Sheet BDD interv
D1: Formulaire | M1: Code: INS-FL-MAT-08
M2: Version: 00
M3: Date : 20/06/2022
M4: Page : 1/1
A5: Date début | B5: Code | C5: Type | D5: Véhicule | E5: Matricule | F5: N Fiche d'intervention | G5: Partie véhicule | H5: Réclamation / problème | I5: Type d'intervention | J5: Détail Intervention | K5: N BS | L5: Temps d'intervention (min) | M5: Temps d'arrêt (min) | N5: Date fin d'intervention | O5: Observations / Avancement | P5: Rappel | Q5: Mois | R5: An
A6: 37450 | B6: 417 | C6: =IF(ISNA(VLOOKUP(Tableau13[[#This Row],[Code]],'Code Véhicule'!$A$4:$C$185,2,0)),"",VLOOKUP(Tableau13[[#This Row],[Code]],'Code Véhicule'!$A$4:$C$185,2,0)) -> Voiture de fonction | D6: =IF(ISNA(VLOOKUP(Tableau13[[#This Row],[Code]],'Code Véhicule'!$A$4:$C$185,3,0)),"",VLOOKUP(Tableau13[[#This Row],[Code]],'Code Véhicule'!$A$4:$C$185,3,0)) -> Berlingo | E6: =IF(ISNA(VLOOKUP(Tableau13[[#This Row],[Code]],'Code Véhicule'!$A$4:$D$185,4,0))," ",VLOOKUP(Tableau13[[#This Row],[Code]],'Code Véhicule'!$A$4:$D$185,4,0)) -> 981-A-73 | F6: 25609 | G6: Entretien | H6: vidange | I6: c | J6: vidange d'huile moteur 15W40 et changement filtre et filtre a huile a gasoil et filtre a air 255314 km | K6: 166239 | L6: 120 | M6: 120 | N6: 44390 | Q6: =MONTH([1]!Tableau13[[#This Row],[Date début]]) -> #REF! | R6: =YEAR([1]!Tableau13[[#This Row],[Date début]]) -> #REF!
A7: 43770 | B7: 401 | C7: =IF(ISNA(VLOOKUP(Tableau13[[#This Row],[Code]],'Code Véhicule'!$A$4:$C$185,2,0)),"",VLOOKUP(Tableau13[[#This Row],[Code]],'Code Véhicule'!$A$4:$C$185,2,0)) -> Camion | D7: =IF(ISNA(VLOOKUP(Tableau13[[#This Row],[Code]],'Code Véhicule'!$A$4:$C$185,3,0)),"",VLOOKUP(Tableau13[[#This Row],[Code]],'Code Véhicule'!$A$4:$C$185,3,0)) -> ISUZU | E7: =IF(ISNA(VLOOKUP(Tableau13[[#This Row],[Code]],'Code Véhicule'!$A$4:$D$185,4,0))," ",VLOOKUP(Tableau13[[#This Row],[Code]],'Code Véhicule'!$A$4:$D$185,4,0)) -> 26128-A-8 | G7: Roue arriere | H7: bruit anormale | I7: C | J7: changement du trampette d'essieu arriere complet a cause d'endommagement du cote roullement coté gauche ( achat du laferaille ) | N7: 43770 | Q7: =MONTH([1]!Tableau13[[#This Row],[Date début]]) -> #REF! | R7: =YEAR([1]!Tableau13[[#This Row],[Date début]]) -> #REF!
A8: 43770 | B8: 434 | C8: =IF(ISNA(VLOOKUP(Tableau13[[#This Row],[Code]],'Code Véhicule'!$A$4:$C$185,2,0)),"",VLOOKUP(Tableau13[[#This Row],[Code]],'Code Véhicule'!$A$4:$C$185,2,0)) -> Chariot elevateur | D8: =IF(ISNA(VLOOKUP(Tableau13[[#This Row],[Code]],'Code Véhicule'!$A$4:$C$185,3,0)),"",VLOOKUP(Tableau13[[#This Row],[Code]],'Code Véhicule'!$A$4:$C$185,3,0)) -> Linde H30D | E8: =IF(ISNA(VLOOKUP(Tableau13[[#This Row],[Code]],'Code Véhicule'!$A$4:$D$185,4,0))," ",VLOOKUP(Tableau13[[#This Row],[Code]],'Code Véhicule'!$A$4:$D$185,4,0)) -> - | G8: Système electrique | H8: mal fonction | I8: C | J8: réparation du tondeur du courroie et changement de courroie de d'alternateur | M8: =IF(ISBLANK(Tableau13[[#This Row],[N BS]]),"",(Tableau13[[#This Row],[N BS]]-Tableau13[[#This Row],[Date début]])) | N8: 43770 | Q8: =MONTH([1]!Tableau13[[#This Row],[Date début]]) -> #REF! | R8: =YEAR([1]!Tableau13[[#This Row],[Date début]]) -> #REF!
A9: 43773 | B9: 481 | C9: =IF(ISNA(VLOOKUP(Tableau13[[#This Row],[Code]],'Code Véhicule'!$A$4:$C$185,2,0)),"",VLOOKUP(Tableau13[[#This Row],[Code]],'Code Véhicule'!$A$4:$C$185,2,0)) -> Camion | D9: =IF(ISNA(VLOOKUP(Tableau13[[#This Row],[Code]],'Code Véhicule'!$A$4:$C$185,3,0)),"",VLOOKUP(Tableau13[[#This Row],[Code]],'Code Véhicule'!$A$4:$C$185,3,0)) -> VOLVO | E9: =IF(ISNA(VLOOKUP(Tableau13[[#This Row],[Code]],'Code Véhicule'!$A$4:$D$185,4,0))," ",VLOOKUP(Tableau13[[#This Row],[Code]],'Code Véhicule'!$A$4:$D$185,4,0)) -> 22300-A-73 | G9: Grue de levage | H9: materielle | I9: C | J9: changement d'elingue de levage des palettes | N9: 43773 | Q9: =MONTH([1]!Tableau13[[#This Row],[Date début]]) -> #REF! | R9: =YEAR([1]!Tableau13[[#This Row],[Date début]]) -> #REF!
A10: 43773 | B10: 480 | C10: =IF(ISNA(VLOOKUP(Tableau13[[#This Row],[Code]],'Code Véhicule'!$A$4:$C$185,2,0)),"",VLOOKUP(Tableau13[[#This Row],[Code]],'Code Véhicule'!$A$4:$C$185,2,0)) -> Camion | D10: =IF(ISNA(VLOOKUP(Tableau13[[#This Row],[Code]],'Code Véhicule'!$A$4:$C$185,3,0)),"",VLOOKUP(Tableau13[[#This Row],[Code]],'Code Véhicule'!$A$4:$C$185,3,0)) -> VOLVO | E10: =IF(ISNA(VLOOKUP(Tableau13[[#This Row],[Code]],'Code Véhicule'!$A$4:$D$185,4,0))," ",VLOOKUP(Tableau13[[#This Row],[Code]],'Code Véhicule'!$A$4:$D$185,4,0)) -> 22299-A-73 | G10: Grue de levage | H10: materielle | I10: C | J10: changement d'elingue de levage des palettes | N10: 43773 | Q10: =MONTH([1]!Tableau13[[#This Row],[Date début]]) -> #REF! | R10: =YEAR([1]!Tableau13[[#This Row],[Date début]]) -> #REF!
A11: 43775 | B11: 406 | C11: =IF(ISNA(VLOOKUP(Tableau13[[#This Row],[Code]],'Code Véhicule'!$A$4:$C$185,2,0)),"",VLOOKUP(Tableau13[[#This Row],[Code]],'Code Véhicule'!$A$4:$C$185,2,0)) -> Semi remorque | D11: =IF(ISNA(VLOOKUP(Tableau13[[#This Row],[Code]],'Code Véhicule'!$A$4:$C$185,3,0)),"",VLOOKUP(Tableau13[[#This Row],[Code]],'Code Véhicule'!$A$4:$C$185,3,0)) -> VOLVO | E11: =IF(ISNA(VLOOKUP(Tableau13[[#This Row],[Code]],'Code Véhicule'!$A$4:$D$185,4,0))," ",VLOOKUP(Tableau13[[#This Row],[Code]],'Code Véhicule'!$A$4:$D$185,4,0)) -> 70352-A-6 | G11: Moteur | H11: bruit anormale | I11: C | J11: changement du support de ventilateur de refroidissemen moteur avec roullement ref 58554 | N11: 43775 | Q11: =MONTH([1]!Tableau13[[#This Row],[Date début]]) -> #REF! | R11: =YEAR([1]!Tableau13[[#This Row],[Date début]]) -> #REF!
A12: 43776 | B12: 482 | C12: =IF(ISNA(VLOOKUP(Tableau13[[#This Row],[Code]],'Code Véhicule'!$A$4:$C$185,2,0)),"",VLOOKUP(Tableau13[[#This Row],[Code]],'Code Véhicule'!$A$4:$C$185,2,0)) -> Pick up | D12: =IF(ISNA(VLOOKUP(Tableau13[[#This Row],[Code]],'Code Véhicule'!$A$4:$C$185,3,0)),"",VLOOKUP(Tableau13[[#This Row],[Code]],'Code Véhicule'!$A$4:$C$185,3,0)) -> HYUNDAI H100 | E12: =IF(ISNA(VLOOKUP(Tableau13[[#This Row],[Code]],'Code Véhicule'!$A$4:$D$185,4,0))," ",VLOOKUP(Tableau13[[#This Row],[Code]],'Code Véhicule'!$A$4:$D$185,4,0)) -> 22368-A-73 | G12: Accessoire | H12: plaque de signale | I12: C | J12: equippement d'engin par galet de securité et plaque d'en panne | N12: 43776 | Q12: =MONTH([1]!Tableau13[[#This Row],[Date début]]) -> #REF! | R12: =YEAR([1]!Tableau13[[#This Row],[Date début]]) -> #REF!
A13: 43776 | B13: 435 | C13: =IF(ISNA(VLOOKUP(Tableau13[[#This Row],[Code]],'Code Véhicule'!$A$4:$C$185,2,0)),"",VLOOKUP(Tableau13[[#This Row],[Code]],'Code Véhicule'!$A$4:$C$185,2,0)) -> Camion | D13: =IF(ISNA(VLOOKUP(Tableau13[[#This Row],[Code]],'Code Véhicule'!$A$4:$C$185,3,0)),"",VLOOKUP(Tableau13[[#This Row],[Code]],'Code Véhicule'!$A$4:$C$185,3,0)) -> Mitsubishi | E13: =IF(ISNA(VLOOKUP(Tableau13[[#This Row],[Code]],'Code Véhicule'!$A$4:$D$185,4,0))," ",VLOOKUP(Tableau13[[#This Row],[Code]],'Code Véhicule'!$A$4:$D$185,4,0)) -> 11469-A-73 | G13: Moteur | H13: vidange | I13: P | J13: vidange d'huile moteur 15W40 341057 km | N13: 43776 | Q13: =MONTH([1]!Tableau13[[#This Row],[Date début]]) -> #REF! | R13: =YEAR([1]!Tableau13[[#This Row],[Date début]]) -> #REF!
A14: 43776 | B14: 410 | C14: =IF(ISNA(VLOOKUP(Tableau13[[#This Row],[Code]],'Code Véhicule'!$A$4:$C$185,2,0)),"",VLOOKUP(Tableau13[[#This Row],[Code]],'Code Véhicule'!$A$4:$C$185,2,0)) -> Semi remorque | D14: =IF(ISNA(VLOOKUP(Tableau13[[#This Row],[Code]],'Code Véhicule'!$A$4:$C$185,3,0)),"",VLOOKUP(Tableau13[[#This Row],[Code]],'Code Véhicule'!$A$4:$C$185,3,0)) -> MAN | E14: =IF(ISNA(VLOOKUP(Tableau13[[#This Row],[Code]],'Code Véhicule'!$A$4:$D$185,4,0))," ",VLOOKUP(Tableau13[[#This Row],[Code]],'Code Véhicule'!$A$4:$D$185,4,0)) -> 28659-D-1 | G14: Accessoire | H14: materielle | I14: C | J14: changement du gilet de securité | N14: 43776 | Q14: =MONTH([1]!Tableau13[[#This Row],[Date début]]) -> #REF! | R14: =YEAR([1]!Tableau13[[#This Row],[Date début]]) -> #REF!
A15: 43776 | B15: 479 | C15: =IF(ISNA(VLOOKUP(Tableau13[[#This Row],[Code]],'Code Véhicule'!$A$4:$C$185,2,0)),"",VLOOKUP(Tableau13[[#This Row],[Code]],'Code Véhicule'!$A$4:$C$185,2,0)) -> Bus de transport | D15: =IF(ISNA(VLOOKUP(Tableau13[[#This Row],[Code]],'Code Véhicule'!$A$4:$C$185,3,0)),"",VLOOKUP(Tableau13[[#This Row],[Code]],'Code Véhicule'!$A$4:$C$185,3,0)) -> Hyundai County | E15: =IF(ISNA(VLOOKUP(Tableau13[[#This Row],[Code]],'Code Véhicule'!$A$4:$D$185,4,0))," ",VLOOKUP(Tableau13[[#This Row],[Code]],'Code Véhicule'!$A$4:$D$185,4,0)) -> 22772-A-73 | G15: Accessoire | H15: materielle | I15: C | J15: changement d'eixtincteur | N15: 43776 | Q15: =MONTH([1]!Tableau13[[#This Row],[Date début]]) -> #REF! | R15: =YEAR([1]!Tableau13[[#This Row],[Date début]]) -> #REF!
A16: 43781 | B16: 411 | C16: =IF(ISNA(VLOOKUP(Tableau13[[#This Row],[Code]],'Code Véhicule'!$A$4:$C$185,2,0)),"",VLOOKUP(Tableau13[[#This Row],[Code]],'Code Véhicule'!$A$4:$C$185,2,0)) -> Camion | D16: =IF(ISNA(VLOOKUP(Tableau13[[#This Row],[Code]],'Code Véhicule'!$A$4:$C$185,3,0)),"",VLOOKUP(Tableau13[[#This Row],[Code]],'Code Véhicule'!$A$4:$C$185,3,0)) -> Renault | E16: =IF(ISNA(VLOOKUP(Tableau13[[#This Row],[Code]],'Code Véhicule'!$A$4:$D$185,4,0))," ",VLOOKUP(Tableau13[[#This Row],[Code]],'Code Véhicule'!$A$4:$D$185,4,0)) -> 25636-A-13 | G16: Grue de levage | H16: materielle | I16: C | J16: changement d'elingue de levage des palettes | N16: 43781 | Q16: =MONTH([1]!Tableau13[[#This Row],[Date début]]) -> #REF! | R16: =YEAR([1]!Tableau13[[#This Row],[Date début]]) -> #REF!
A17: 43781 | B17: 439 | C17: =IF(ISNA(VLOOKUP(Tableau13[[#This Row],[Code]],'Code Véhicule'!$A$4:$C$185,2,0)),"",VLOOKUP(Tableau13[[#This Row],[Code]],'Code Véhicule'!$A$4:$C$185,2,0)) -> Semi remorque | D17: =IF(ISNA(VLOOKUP(Tableau13[[#This Row],[Code]],'Code Véhicule'!$A$4:$C$185,3,0)),"",VLOOKUP(Tableau13[[#This Row],[Code]],'Code Véhicule'!$A$4:$C$185,3,0)) -> VOLVO | E17: =IF(ISNA(VLOOKUP(Tableau13[[#This Row],[Code]],'Code Véhicule'!$A$4:$D$185,4,0))," ",VLOOKUP(Tableau13[[#This Row],[Code]],'Code Véhicule'!$A$4:$D$185,4,0)) -> 17886-A-73 | G17: Système electrique | H17: eclairage | I17: C | J17: réparation d'eclairage et changemet des lampes | N17: 43781 | Q17: =MONTH([1]!Tableau13[[#This Row],[Date début]]) -> #REF! | R17: =YEAR([1]!Tableau13[[#This Row],[Date début]]) -> #REF!
A18: 43781 | B18: 410 | C18: =IF(ISNA(VLOOKUP(Tableau13[[#This Row],[Code]],'Code Véhicule'!$A$4:$C$185,2,0)),"",VLOOKUP(Tableau13[[#This Row],[Code]],'Code Véhicule'!$A$4:$C$185,2,0)) -> Semi remorque | D18: =IF(ISNA(VLOOKUP(Tableau13[[#This Row],[Code]],'Code Véhicule'!$A$4:$C$185,3,0)),"",VLOOKUP(Tableau13[[#This Row],[Code]],'Code Véhicule'!$A$4:$C$185,3,0)) -> MAN | E18: =IF(ISNA(VLOOKUP(Tableau13[[#This Row],[Code]],'Code Véhicule'!$A$4:$D$185,4,0))," ",VLOOKUP(Tableau13[[#This Row],[Code]],'Code Véhicule'!$A$4:$D$185,4,0)) -> 28659-D-1 | G18: Système electrique | H18: eclairage | I18: C | J18: réparation d'eclairage et changemet des lampes | N18: 43781 | Q18: =MONTH([1]!Tableau13[[#This Row],[Date début]]) -> #REF! | R18: =YEAR([1]!Tableau13[[#This Row],[Date début]]) -> #REF!
A19: 43781 | B19: 438 | C19: =IF(ISNA(VLOOKUP(Tableau13[[#This Row],[Code]],'Code Véhicule'!$A$4:$C$185,2,0)),"",VLOOKUP(Tableau13[[#This Row],[Code]],'Code Véhicule'!$A$4:$C$185,2,0)) -> Semi remorque | D19: =IF(ISNA(VLOOKUP(Tableau13[[#This Row],[Code]],'Code Véhicule'!$A$4:$C$185,3,0)),"",VLOOKUP(Tableau13[[#This Row],[Code]],'Code Véhicule'!$A$4:$C$185,3,0)) -> VOLVO | E19: =IF(ISNA(VLOOKUP(Tableau13[[#This Row],[Code]],'Code Véhicule'!$A$4:$D$185,4,0))," ",VLOOKUP(Tableau13[[#This Row],[Code]],'Code Véhicule'!$A$4:$D$185,4,0)) -> 17885-A-73 | G19: Système electrique | H19: eclairage | I19: C | J19: réparation d'eclairage et changemet des lampes | N19: 43781 | Q19: =MONTH([1]!Tableau13[[#This Row],[Date début]]) -> #REF! | R19: =YEAR([1]!Tableau13[[#This Row],[Date début]]) -> #REF!
A20: 43782 | B20: 408 | C20: =IF(ISNA(VLOOKUP(Tableau13[[#This Row],[Code]],'Code Véhicule'!$A$4:$C$185,2,0)),"",VLOOKUP(Tableau13[[#This Row],[Code]],'Code Véhicule'!$A$4:$C$185,2,0)) -> Camion | D20: =IF(ISNA(VLOOKUP(Tableau13[[#This Row],[Code]],'Code Véhicule'!$A$4:$C$185,3,0)),"",VLOOKUP(Tableau13[[#This Row],[Code]],'Code Véhicule'!$A$4:$C$185,3,0)) -> Mitsubishi | E20: =IF(ISNA(VLOOKUP(Tableau13[[#This Row],[Code]],'Code Véhicule'!$A$4:$D$185,4,0))," ",VLOOKUP(Tableau13[[#This Row],[Code]],'Code Véhicule'!$A$4:$D$185,4,0)) -> 4703-A-73 | G20: Direction assisté | H20: vidange | I20: C | J20: réparation du probleme de direction assisté | N20: 43782 | Q20: =MONTH([1]!Tableau13[[#This Row],[Date début]]) -> #REF! | R20: =YEAR([1]!Tableau13[[#This Row],[Date début]]) -> #REF!
A21: 43783 | B21: 411 | C21: =IF(ISNA(VLOOKUP(Tableau13[[#This Row],[Code]],'Code Véhicule'!$A$4:$C$185,2,0)),"",VLOOKUP(Tableau13[[#This Row],[Code]],'Code Véhicule'!$A$4:$C$185,2,0)) -> Camion | D21: =IF(ISNA(VLOOKUP(Tableau13[[#This Row],[Code]],'Code Véhicule'!$A$4:$C$185,3,0)),"",VLOOKUP(Tableau13[[#This Row],[Code]],'Code Véhicule'!$A$4:$C$185,3,0)) -> Renault | E21: =IF(ISNA(VLOOKUP(Tableau13[[#This Row],[Code]],'Code Véhicule'!$A$4:$D$185,4,0))," ",VLOOKUP(Tableau13[[#This Row],[Code]],'Code Véhicule'!$A$4:$D$185,4,0)) -> 25636-A-13 | G21: Embrayage | H21: mal fonction | I21: C | J21: réparation et réglage du jeu d'embrayage purge du circuit d'huile | N21: 43783 | Q21: =MONTH([1]!Tableau13[[#This Row],[Date début]]) -> #REF! | R21: =YEAR([1]!Tableau13[[#This Row],[Date début]]) -> #REF!
A22: 43784 | B22: 414 | C22: =IF(ISNA(VLOOKUP(Tableau13[[#This Row],[Code]],'Code Véhicule'!$A$4:$C$185,2,0)),"",VLOOKUP(Tableau13[[#This Row],[Code]],'Code Véhicule'!$A$4:$C$185,2,0)) -> Balayeuse | D22: =IF(ISNA(VLOOKUP(Tableau13[[#This Row],[Code]],'Code Véhicule'!$A$4:$C$185,3,0)),"",VLOOKUP(Tableau13[[#This Row],[Code]],'Code Véhicule'!$A$4:$C$185,3,0)) -> Bobcat | E22: =IF(ISNA(VLOOKUP(Tableau13[[#This Row],[Code]],'Code Véhicule'!$A$4:$D$185,4,0))," ",VLOOKUP(Tableau13[[#This Row],[Code]],'Code Véhicule'!$A$4:$D$185,4,0)) -> - | G22: Mécanique | I22: C | J22: changement du brosse de netoyage changement battrie de démarrage + courroie de ventulateur +vidange d'huile moteur et changeent du filtre a huile + gasoil+ hydraulique répartion et soudage du goudet de netoyage | M22: =IF(ISBLANK(Tableau13[[#This Row],[N BS]]),"",(Tableau13[[#This Row],[N BS]]-Tableau13[[#This Row],[Date début]])) | N22: 43784 | Q22: =MONTH([1]!Tableau13[[#This Row],[Date début]]) -> #REF! | R22: =YEAR([1]!Tableau13[[#This Row],[Date début]]) -> #REF!
A23: 43785 | B23: 406 | C23: =IF(ISNA(VLOOKUP(Tableau13[[#This Row],[Code]],'Code Véhicule'!$A$4:$C$185,2,0)),"",VLOOKUP(Tableau13[[#This Row],[Code]],'Code Véhicule'!$A$4:$C$185,2,0)) -> Semi remorque | D23: =IF(ISNA(VLOOKUP(Tableau13[[#This Row],[Code]],'Code Véhicule'!$A$4:$C$185,3,0)),"",VLOOKUP(Tableau13[[#This Row],[Code]],'Code Véhicule'!$A$4:$C$185,3,0)) -> VOLVO | E23: =IF(ISNA(VLOOKUP(Tableau13[[#This Row],[Code]],'Code Véhicule'!$A$4:$D$185,4,0))," ",VLOOKUP(Tableau13[[#This Row],[Code]],'Code Véhicule'!$A$4:$D$185,4,0)) -> 70352-A-6 | G23: Système electrique | H23: electrique | I23: C | J23: réparation du probléme de démarrage | N23: 43785 | Q23: =MONTH([1]!Tableau13[[#This Row],[Date début]]) -> #REF! | R23: =YEAR([1]!Tableau13[[#This Row],[Date début]]) -> #REF!
A24: 43785 | B24: 410 | C24: =IF(ISNA(VLOOKUP(Tableau13[[#This Row],[Code]],'Code Véhicule'!$A$4:$C$185,2,0)),"",VLOOKUP(Tableau13[[#This Row],[Code]],'Code Véhicule'!$A$4:$C$185,2,0)) -> Semi remorque | D24: =IF(ISNA(VLOOKUP(Tableau13[[#This Row],[Code]],'Code Véhicule'!$A$4:$C$185,3,0)),"",VLOOKUP(Tableau13[[#This Row],[Code]],'Code Véhicule'!$A$4:$C$185,3,0)) -> MAN | E24: =IF(ISNA(VLOOKUP(Tableau13[[#This Row],[Code]],'Code Véhicule'!$A$4:$D$185,4,0))," ",VLOOKUP(Tableau13[[#This Row],[Code]],'Code Véhicule'!$A$4:$D$185,4,0)) -> 28659-D-1 | G24: Moteur | H24: electrique | I24: C | J24: réparation du probleme de démarrage du moteur et changement des filtres et netoyage du reservoire de gasoil | N24: 43785 | Q24: =MONTH([1]!Tableau13[[#This Row],[Date début]]) -> #REF! | R24: =YEAR([1]!Tableau13[[#This Row],[Date début]]) -> #REF!
A25: 43785 | B25: 411 | C25: =IF(ISNA(VLOOKUP(Tableau13[[#This Row],[Code]],'Code Véhicule'!$A$4:$C$185,2,0)),"",VLOOKUP(Tableau13[[#This Row],[Code]],'Code Véhicule'!$A$4:$C$185,2,0)) -> Camion | D25: =IF(ISNA(VLOOKUP(Tableau13[[#This Row],[Code]],'Code Véhicule'!$A$4:$C$185,3,0)),"",VLOOKUP(Tableau13[[#This Row],[Code]],'Code Véhicule'!$A$4:$C$185,3,0)) -> Renault | E25: =IF(ISNA(VLOOKUP(Tableau13[[#This Row],[Code]],'Code Véhicule'!$A$4:$D$185,4,0))," ",VLOOKUP(Tableau13[[#This Row],[Code]],'Code Véhicule'!$A$4:$D$185,4,0)) -> 25636-A-13 | G25: Embrayage | I25: C | J25: changement du kit d'embrayage complet (disque ,plateau et butée ) changement du support cardon changement du pompe d'embrayege inferieur vidange d'huile moteur et pontarriere et boite de vitesse 576773 km | K25: 43792 | N25: 43785 | Q25: =MONTH([1]!Tableau13[[#This Row],[Date début]]) -> #REF! | R25: =YEAR([1]!Tableau13[[#This Row],[Date début]]) -> #REF!
A26: 43788 | B26: 429 | C26: =IF(ISNA(VLOOKUP(Tableau13[[#This Row],[Code]],'Code Véhicule'!$A$4:$C$185,2,0)),"",VLOOKUP(Tableau13[[#This Row],[Code]],'Code Véhicule'!$A$4:$C$185,2,0)) -> Chariot elevateur | D26: =IF(ISNA(VLOOKUP(Tableau13[[#This Row],[Code]],'Code Véhicule'!$A$4:$C$185,3,0)),"",VLOOKUP(Tableau13[[#This Row],[Code]],'Code Véhicule'!$A$4:$C$185,3,0)) -> Fenwick HD30 | E26: =IF(ISNA(VLOOKUP(Tableau13[[#This Row],[Code]],'Code Véhicule'!$A$4:$D$185,4,0))," ",VLOOKUP(Tableau13[[#This Row],[Code]],'Code Véhicule'!$A$4:$D$185,4,0)) -> - | G26: Entretien | H26: vidange | I26: P | J26: mise a niveau d'huile hydraulique | M26: =IF(ISBLANK(Tableau13[[#This Row],[N BS]]),"",(Tableau13[[#This Row],[N BS]]-Tableau13[[#This Row],[Date début]])) | N26: 43788 | Q26: =MONTH([1]!Tableau13[[#This Row],[Date début]]) -> #REF! | R26: =YEAR([1]!Tableau13[[#This Row],[Date début]]) -> #REF!
A27: 43789 | B27: 436 | C27: =IF(ISNA(VLOOKUP(Tableau13[[#This Row],[Code]],'Code Véhicule'!$A$4:$C$185,2,0)),"",VLOOKUP(Tableau13[[#This Row],[Code]],'Code Véhicule'!$A$4:$C$185,2,0)) -> Camion | D27: =IF(ISNA(VLOOKUP(Tableau13[[#This Row],[Code]],'Code Véhicule'!$A$4:$C$185,3,0)),"",VLOOKUP(Tableau13[[#This Row],[Code]],'Code Véhicule'!$A$4:$C$185,3,0)) -> Mitsubishi | E27: =IF(ISNA(VLOOKUP(Tableau13[[#This Row],[Code]],'Code Véhicule'!$A$4:$D$185,4,0))," ",VLOOKUP(Tableau13[[#This Row],[Code]],'Code Véhicule'!$A$4:$D$185,4,0)) -> 11470-A-73 | G27: Pneu | H27: pneu | I27: C | J27: changement des quatre pneus ref 12R22,5 | N27: 43789 | Q27: =MONTH([1]!Tableau13[[#This Row],[Date début]]) -> #REF! | R27: =YEAR([1]!Tableau13[[#This Row],[Date début]]) -> #REF!
A28: 43790 | B28: 471 | C28: =IF(ISNA(VLOOKUP(Tableau13[[#This Row],[Code]],'Code Véhicule'!$A$4:$C$185,2,0)),"",VLOOKUP(Tableau13[[#This Row],[Code]],'Code Véhicule'!$A$4:$C$185,2,0)) -> Bus de transport | D28: =IF(ISNA(VLOOKUP(Tableau13[[#This Row],[Code]],'Code Véhicule'!$A$4:$C$185,3,0)),"",VLOOKUP(Tableau13[[#This Row],[Code]],'Code Véhicule'!$A$4:$C$185,3,0)) -> Hyundai County | E28: =IF(ISNA(VLOOKUP(Tableau13[[#This Row],[Code]],'Code Véhicule'!$A$4:$D$185,4,0))," ",VLOOKUP(Tableau13[[#This Row],[Code]],'Code Véhicule'!$A$4:$D$185,4,0)) -> 18516-A-73 | G28: Système electrique | H28: eclairage | I28: C | J28: réparation du probleme d'eclairage | N28: 43790 | Q28: =MONTH([1]!Tableau13[[#This Row],[Date début]]) -> #REF! | R28: =YEAR([1]!Tableau13[[#This Row],[Date début]]) -> #REF!
A29: 43791 | B29: 439 | C29: =IF(ISNA(VLOOKUP(Tableau13[[#This Row],[Code]],'Code Véhicule'!$A$4:$C$185,2,0)),"",VLOOKUP(Tableau13[[#This Row],[Code]],'Code Véhicule'!$A$4:$C$185,2,0)) -> Semi remorque | D29: =IF(ISNA(VLOOKUP(Tableau13[[#This Row],[Code]],'Code Véhicule'!$A$4:$C$185,3,0)),"",VLOOKUP(Tableau13[[#This Row],[Code]],'Code Véhicule'!$A$4:$C$185,3,0)) -> VOLVO | E29: =IF(ISNA(VLOOKUP(Tableau13[[#This Row],[Code]],'Code Véhicule'!$A$4:$D$185,4,0))," ",VLOOKUP(Tableau13[[#This Row],[Code]],'Code Véhicule'!$A$4:$D$185,4,0)) -> 17886-A-73 | G29: Moteur | H29: mal fonction | I29: C | J29: changement du bouchon de gasoil | N29: 43791 | Q29: =MONTH([1]!Tableau13[[#This Row],[Date début]]) -> #REF! | R29: =YEAR([1]!Tableau13[[#This Row],[Date début]]) -> #REF!
A30: 43791 | B30: 409 | C30: =IF(ISNA(VLOOKUP(Tableau13[[#This Row],[Code]],'Code Véhicule'!$A$4:$C$185,2,0)),"",VLOOKUP(Tableau13[[#This Row],[Code]],'Code Véhicule'!$A$4:$C$185,2,0)) -> Camion | D30: =IF(ISNA(VLOOKUP(Tableau13[[#This Row],[Code]],'Code Véhicule'!$A$4:$C$185,3,0)),"",VLOOKUP(Tableau13[[#This Row],[Code]],'Code Véhicule'!$A$4:$C$185,3,0)) -> Mitsubishi | E30: =IF(ISNA(VLOOKUP(Tableau13[[#This Row],[Code]],'Code Véhicule'!$A$4:$D$185,4,0))," ",VLOOKUP(Tableau13[[#This Row],[Code]],'Code Véhicule'!$A$4:$D$185,4,0)) -> 4969-A-73 | G30: Moteur | H30: vidange | I30: P | J30: vidange d'huile moteur et changement di filtre a huile et gasoil lavage et graissage generale d'engin réparation du fuuite d'air comprimé lavage et graissage generale d'engin | N30: 43791 | Q30: =MONTH([1]!Tableau13[[#This Row],[Date début]]) -> #REF! | R30: =YEAR([1]!Tableau13[[#This Row],[Date début]]) -> #REF!
A31: 43791 | B31: 413 | C31: =IF(ISNA(VLOOKUP(Tableau13[[#This Row],[Code]],'Code Véhicule'!$A$4:$C$185,2,0)),"",VLOOKUP(Tableau13[[#This Row],[Code]],'Code Véhicule'!$A$4:$C$185,2,0)) -> Chargeur | D31: =IF(ISNA(VLOOKUP(Tableau13[[#This Row],[Code]],'Code Véhicule'!$A$4:$C$185,3,0)),"",VLOOKUP(Tableau13[[#This Row],[Code]],'Code Véhicule'!$A$4:$C$185,3,0)) -> Caterpillar | E31: =IF(ISNA(VLOOKUP(Tableau13[[#This Row],[Code]],'Code Véhicule'!$A$4:$D$185,4,0))," ",VLOOKUP(Tableau13[[#This Row],[Code]],'Code Véhicule'!$A$4:$D$185,4,0)) -> - | G31: Système electrique | H31: mal fonction | I31: C | J31: réparation du probleme de mache avant arriere mise a niveau d'huile hydraulique | M31: =IF(ISBLANK(Tableau13[[#This Row],[N BS]]),"",(Tableau13[[#This Row],[N BS]]-Tableau13[[#This Row],[Date début]])) | N31: 43791 | Q31: =MONTH([1]!Tableau13[[#This Row],[Date début]]) -> #REF! | R31: =YEAR([1]!Tableau13[[#This Row],[Date début]]) -> #REF!
A32: 43791 | B32: 435 | C32: =IF(ISNA(VLOOKUP(Tableau13[[#This Row],[Code]],'Code Véhicule'!$A$4:$C$185,2,0)),"",VLOOKUP(Tableau13[[#This Row],[Code]],'Code Véhicule'!$A$4:$C$185,2,0)) -> Camion | D32: =IF(ISNA(VLOOKUP(Tableau13[[#This Row],[Code]],'Code Véhicule'!$A$4:$C$185,3,0)),"",VLOOKUP(Tableau13[[#This Row],[Code]],'Code Véhicule'!$A$4:$C$185,3,0)) -> Mitsubishi | E32: =IF(ISNA(VLOOKUP(Tableau13[[#This Row],[Code]],'Code Véhicule'!$A$4:$D$185,4,0))," ",VLOOKUP(Tableau13[[#This Row],[Code]],'Code Véhicule'!$A$4:$D$185,4,0)) -> 11469-A-73 | G32: suspension | I32: C | J32: réparation des element de susponsion | K32: 43792 | N32: 43791 | Q32: =MONTH([1]!Tableau13[[#This Row],[Date début]]) -> #REF! | R32: =YEAR([1]!Tableau13[[#This Row],[Date début]]) -> #REF!
A33: 43793 | B33: 429 | C33: =IF(ISNA(VLOOKUP(Tableau13[[#This Row],[Code]],'Code Véhicule'!$A$4:$C$185,2,0)),"",VLOOKUP(Tableau13[[#This Row],[Code]],'Code Véhicule'!$A$4:$C$185,2,0)) -> Chariot elevateur | D33: =IF(ISNA(VLOOKUP(Tableau13[[#This Row],[Code]],'Code Véhicule'!$A$4:$C$185,3,0)),"",VLOOKUP(Tableau13[[#This Row],[Code]],'Code Véhicule'!$A$4:$C$185,3,0)) -> Fenwick HD30 | E33: =IF(ISNA(VLOOKUP(Tableau13[[#This Row],[Code]],'Code Véhicule'!$A$4:$D$185,4,0))," ",VLOOKUP(Tableau13[[#This Row],[Code]],'Code Véhicule'!$A$4:$D$185,4,0)) -> - | G33: Roue arriere | H33: mal fonction | I33: C | J33: changement du kit réparation d'axe fusee | M33: =IF(ISBLANK(Tableau13[[#This Row],[N BS]]),"",(Tableau13[[#This Row],[N BS]]-Tableau13[[#This Row],[Date début]])) | N33: 43793 | Q33: =MONTH([1]!Tableau13[[#This Row],[Date début]]) -> #REF! | R33: =YEAR([1]!Tableau13[[#This Row],[Date début]]) -> #REF!
A34: 43794 | B34: 403 | C34: =IF(ISNA(VLOOKUP(Tableau13[[#This Row],[Code]],'Code Véhicule'!$A$4:$C$185,2,0)),"",VLOOKUP(Tableau13[[#This Row],[Code]],'Code Véhicule'!$A$4:$C$185,2,0)) -> Camion | D34: =IF(ISNA(VLOOKUP(Tableau13[[#This Row],[Code]],'Code Véhicule'!$A$4:$C$185,3,0)),"",VLOOKUP(Tableau13[[#This Row],[Code]],'Code Véhicule'!$A$4:$C$185,3,0)) -> MAN | E34: =IF(ISNA(VLOOKUP(Tableau13[[#This Row],[Code]],'Code Véhicule'!$A$4:$D$185,4,0))," ",VLOOKUP(Tableau13[[#This Row],[Code]],'Code Véhicule'!$A$4:$D$185,4,0)) -> 4790-B-8 | G34: Accessoire | I34: c | J34: montage des auto coulant | N34: 43794 | Q34: =MONTH([1]!Tableau13[[#This Row],[Date début]]) -> #REF! | R34: =YEAR([1]!Tableau13[[#This Row],[Date début]]) -> #REF!
A35: 43795 | B35: 410 | C35: =IF(ISNA(VLOOKUP(Tableau13[[#This Row],[Code]],'Code Véhicule'!$A$4:$C$185,2,0)),"",VLOOKUP(Tableau13[[#This Row],[Code]],'Code Véhicule'!$A$4:$C$185,2,0)) -> Semi remorque | D35: =IF(ISNA(VLOOKUP(Tableau13[[#This Row],[Code]],'Code Véhicule'!$A$4:$C$185,3,0)),"",VLOOKUP(Tableau13[[#This Row],[Code]],'Code Véhicule'!$A$4:$C$185,3,0)) -> MAN | E35: =IF(ISNA(VLOOKUP(Tableau13[[#This Row],[Code]],'Code Véhicule'!$A$4:$D$185,4,0))," ",VLOOKUP(Tableau13[[#This Row],[Code]],'Code Véhicule'!$A$4:$D$185,4,0)) -> 28659-D-1 | G35: Freinage | I35: C | J35: changement du came de réglage frein cote arriere droit du tracteur et optique avant droit | N35: 43795 | Q35: =MONTH([1]!Tableau13[[#This Row],[Date début]]) -> #REF! | R35: =YEAR([1]!Tableau13[[#This Row],[Date début]]) -> #REF!
A36: 43795 | B36: 435 | C36: =IF(ISNA(VLOOKUP(Tableau13[[#This Row],[Code]],'Code Véhicule'!$A$4:$C$185,2,0)),"",VLOOKUP(Tableau13[[#This Row],[Code]],'Code Véhicule'!$A$4:$C$185,2,0)) -> Camion | D36: =IF(ISNA(VLOOKUP(Tableau13[[#This Row],[Code]],'Code Véhicule'!$A$4:$C$185,3,0)),"",VLOOKUP(Tableau13[[#This Row],[Code]],'Code Véhicule'!$A$4:$C$185,3,0)) -> Mitsubishi | E36: =IF(ISNA(VLOOKUP(Tableau13[[#This Row],[Code]],'Code Véhicule'!$A$4:$D$185,4,0))," ",VLOOKUP(Tableau13[[#This Row],[Code]],'Code Véhicule'!$A$4:$D$185,4,0)) -> 11469-A-73 | G36: Grue de levage | I36: C | N36: 43795 | Q36: =MONTH([1]!Tableau13[[#This Row],[Date début]]) -> #REF! | R36: =YEAR([1]!Tableau13[[#This Row],[Date début]]) -> #REF!
A37: 43797 | B37: 428 | C37: =IF(ISNA(VLOOKUP(Tableau13[[#This Row],[Code]],'Code Véhicule'!$A$4:$C$185,2,0)),"",VLOOKUP(Tableau13[[#This Row],[Code]],'Code Véhicule'!$A$4:$C$185,2,0)) -> Chariot elevateur | D37: =IF(ISNA(VLOOKUP(Tableau13[[#This Row],[Code]],'Code Véhicule'!$A$4:$C$185,3,0)),"",VLOOKUP(Tableau13[[#This Row],[Code]],'Code Véhicule'!$A$4:$C$185,3,0)) -> Linde H30 | E37: =IF(ISNA(VLOOKUP(Tableau13[[#This Row],[Code]],'Code Véhicule'!$A$4:$D$185,4,0))," ",VLOOKUP(Tableau13[[#This Row],[Code]],'Code Véhicule'!$A$4:$D$185,4,0)) -> - | G37: Entretien | H37: vidange | I37: P | J37: vidange d'huilemoteur 15W40 lavage tet graissage generale d'engin | M37: =IF(ISBLANK(Tableau13[[#This Row],[N BS]]),"",(Tableau13[[#This Row],[N BS]]-Tableau13[[#This Row],[Date début]])) | N37: 43797 | Q37: =MONTH([1]!Tableau13[[#This Row],[Date début]]) -> #REF! | R37: =YEAR([1]!Tableau13[[#This Row],[Date début]]) -> #REF!
A38: 43797 | B38: 426 | C38: =IF(ISNA(VLOOKUP(Tableau13[[#This Row],[Code]],'Code Véhicule'!$A$4:$C$185,2,0)),"",VLOOKUP(Tableau13[[#This Row],[Code]],'Code Véhicule'!$A$4:$C$185,2,0)) -> Chariot elevateur | D38: =IF(ISNA(VLOOKUP(Tableau13[[#This Row],[Code]],'Code Véhicule'!$A$4:$C$185,3,0)),"",VLOOKUP(Tableau13[[#This Row],[Code]],'Code Véhicule'!$A$4:$C$185,3,0)) -> Manitou MC 30 | E38: =IF(ISNA(VLOOKUP(Tableau13[[#This Row],[Code]],'Code Véhicule'!$A$4:$D$185,4,0))," ",VLOOKUP(Tableau13[[#This Row],[Code]],'Code Véhicule'!$A$4:$D$185,4,0)) -> - | G38: Système electrique | I38: C | J38: réparation d'eclairage et changemet des lampes | M38: =IF(ISBLANK(Tableau13[[#This Row],[N BS]]),"",(Tableau13[[#This Row],[N BS]]-Tableau13[[#This Row],[Date début]])) | N38: 43797 | Q38: =MONTH([1]!Tableau13[[#This Row],[Date début]]) -> #REF! | R38: =YEAR([1]!Tableau13[[#This Row],[Date début]]) -> #REF!
A39: 43797 | B39: 407 | C39: =IF(ISNA(VLOOKUP(Tableau13[[#This Row],[Code]],'Code Véhicule'!$A$4:$C$185,2,0)),"",VLOOKUP(Tableau13[[#This Row],[Code]],'Code Véhicule'!$A$4:$C$185,2,0)) -> Semi remorque | D39: =IF(ISNA(VLOOKUP(Tableau13[[#This Row],[Code]],'Code Véhicule'!$A$4:$C$185,3,0)),"",VLOOKUP(Tableau13[[#This Row],[Code]],'Code Véhicule'!$A$4:$C$185,3,0)) -> MAN | E39: =IF(ISNA(VLOOKUP(Tableau13[[#This Row],[Code]],'Code Véhicule'!$A$4:$D$185,4,0))," ",VLOOKUP(Tableau13[[#This Row],[Code]],'Code Véhicule'!$A$4:$D$185,4,0)) -> 706-A-73 | G39: pneu | I39: C | J39: réparation du crevaison pneu par meche de réparation | K39: 43797 | N39: 43797 | Q39: =MONTH([1]!Tableau13[[#This Row],[Date début]]) -> #REF! | R39: =YEAR([1]!Tableau13[[#This Row],[Date début]]) -> #REF!
A40: 43797 | B40: 433 | C40: =IF(ISNA(VLOOKUP(Tableau13[[#This Row],[Code]],'Code Véhicule'!$A$4:$C$185,2,0)),"",VLOOKUP(Tableau13[[#This Row],[Code]],'Code Véhicule'!$A$4:$C$185,2,0)) -> Voiture de fonction | D40: =IF(ISNA(VLOOKUP(Tableau13[[#This Row],[Code]],'Code Véhicule'!$A$4:$C$185,3,0)),"",VLOOKUP(Tableau13[[#This Row],[Code]],'Code Véhicule'!$A$4:$C$185,3,0)) -> Berlingo | E40: =IF(ISNA(VLOOKUP(Tableau13[[#This Row],[Code]],'Code Véhicule'!$A$4:$D$185,4,0))," ",VLOOKUP(Tableau13[[#This Row],[Code]],'Code Véhicule'!$A$4:$D$185,4,0)) -> 10551-A-73 | G40: Moteur | I40: P | J40: vidange d'huile moteur et changement dufiltre a huile | K40: 43797 | N40: 43797 | Q40: =MONTH([1]!Tableau13[[#This Row],[Date début]]) -> #REF! | R40: =YEAR([1]!Tableau13[[#This Row],[Date début]]) -> #REF!
...

Sheet KPI PARC AUTO
A1: An | B1: (Plusieurs éléments)
A2: Mois | B2: (Plusieurs éléments)
A3: Date fin d'intervention | B3: (Tous)
A4: Type | B4: (Tous)
A6: Étiquettes de lignes | B6: Véhicule | C6: Matricule | D6: Nombre de Détail Intervention | F6: MTBF | G6: MTTR | H6: Disponibilité | I6: Objectif
F7: =IF(ISBLANK(B7),"",((540*26-E7)/D7)) | G7: =IF(ISBLANK(B7),"",(E7/D7)) | H7: =IF(ISBLANK(B7),"",((F7/(F7+G7))*100)) | I7: =IF(ISBLANK(B7),"",90)
F8: =IF(ISBLANK(B8),"",((540*26-E8)/D8)) | G8: =IF(ISBLANK(B8),"",(E8/D8)) | H8: =IF(ISBLANK(B8),"",((F8/(F8+G8))*100)) | I8: =IF(ISBLANK(B8),"",90)
F9: =IF(ISBLANK(B9),"",((540*26-E9)/D9)) | G9: =IF(ISBLANK(B9),"",(E9/D9)) | H9: =IF(ISBLANK(B9),"",((F9/(F9+G9))*100)) | I9: =IF(ISBLANK(B9),"",90)
F10: =IF(ISBLANK(B10),"",((540*26-E10)/D10)) | G10: =IF(ISBLANK(B10),"",(E10/D10)) | H10: =IF(ISBLANK(B10),"",((F10/(F10+G10))*100)) | I10: =IF(ISBLANK(B10),"",90)
F11: =IF(ISBLANK(B11),"",((540*26-E11)/D11)) | G11: =IF(ISBLANK(B11),"",(E11/D11)) | H11: =IF(ISBLANK(B11),"",((F11/(F11+G11))*100)) | I11: =IF(ISBLANK(B11),"",90)
F12: =IF(ISBLANK(B12),"",((540*26-E12)/D12)) | G12: =IF(ISBLANK(B12),"",(E12/D12)) | H12: =IF(ISBLANK(B12),"",((F12/(F12+G12))*100)) | I12: =IF(ISBLANK(B12),"",90)
F13: =IF(ISBLANK(B13),"",((540*26-E13)/D13)) | G13: =IF(ISBLANK(B13),"",(E13/D13)) | H13: =IF(ISBLANK(B13),"",((F13/(F13+G13))*100)) | I13: =IF(ISBLANK(B13),"",90)
F14: =IF(ISBLANK(B14),"",((540*26-E14)/D14)) | G14: =IF(ISBLANK(B14),"",(E14/D14)) | H14: =IF(ISBLANK(B14),"",((F14/(F14+G14))*100)) | I14: =IF(ISBLANK(B14),"",90)
F15: =IF(ISBLANK(B15),"",((540*26-E15)/D15)) | G15: =IF(ISBLANK(B15),"",(E15/D15)) | H15: =IF(ISBLANK(B15),"",((F15/(F15+G15))*100)) | I15: =IF(ISBLANK(B15),"",90)
F16: =IF(ISBLANK(B16),"",((540*26-E16)/D16)) | G16: =IF(ISBLANK(B16),"",(E16/D16)) | H16: =IF(ISBLANK(B16),"",((F16/(F16+G16))*100)) | I16: =IF(ISBLANK(B16),"",90)
F17: =IF(ISBLANK(B17),"",((540*26-E17)/D17)) | G17: =IF(ISBLANK(B17),"",(E17/D17)) | H17: =IF(ISBLANK(B17),"",((F17/(F17+G17))*100)) | I17: =IF(ISBLANK(B17),"",90)
F18: =IF(ISBLANK(B18),"",((540*26-E18)/D18)) | G18: =IF(ISBLANK(B18),"",(E18/D18)) | H18: =IF(ISBLANK(B18),"",((F18/(F18+G18))*100)) | I18: =IF(ISBLANK(B18),"",90)
... F53: =IF(ISBLANK(B53),"",((540*26-E53)/D53)) | G53: =IF(ISBLANK(B53),"",(E53/D53)) | H53: =IF(ISBLANK(B53),"",((F53/(F53+G53))*100)) | I53: =IF(ISBLANK(B53),"",90)
F54: =IF(ISBLANK(B54),"",((540*26-E54)/D54)) | G54: =IF(ISBLANK(B54),"",(E54/D54)) | I54: =IF(ISBLANK(B54),"",90)
F55: =IF(ISBLANK(B55),"",((540*26-E55)/D55)) | G55: =IF(ISBLANK(B55),"",(E55/D55)) | I55: =IF(ISBLANK(B55),"",90)
F56: =IF(ISBLANK(B56),"",((540*26-E56)/D56)) | G56: =IF(ISBLANK(B56),"",(E56/D56)) | I56: =IF(ISBLANK(B56),"",90)
F57: =IF(ISBLANK(B57),"",((540*26-E57)/D57)) | G57: =IF(ISBLANK(B57),"",(E57/D57)) | I57: =IF(ISBLANK(B57),"",90)
F58: =IF(ISBLANK(B58),"",((540*26-E58)/D58)) | G58: =IF(ISBLANK(B58),"",(E58/D58)) | I58: =IF(ISBLANK(B58),"",90)
F59: =IF(ISBLANK(B59),"",((540*26-E59)/D59)) | G59: =IF(ISBLANK(B59),"",(E59/D59)) | I59: =IF(ISBLANK(B59),"",90)
F60: =IF(ISBLANK(B60),"",((540*26-E60)/D60)) | G60: =IF(ISBLANK(B60),"",(E60/D60)) | I60: =IF(ISBLANK(B60),"",90)
F61: =IF(ISBLANK(B61),"",((540*26-E61)/D61)) | G61: =IF(ISBLANK(B61),"",(E61/D61)) | I61: =IF(ISBLANK(B61),"",90)
F62: =IF(ISBLANK(B62),"",((540*26-E62)/D62)) | G62: =IF(ISBLANK(B62),"",(E62/D62)) | I62: =IF(ISBLANK(B62),"",90)
F63: =IF(ISBLANK(B63),"",((540*26-E63)/D63)) | G63: =IF(ISBLANK(B63),"",(E63/D63)) | I63: =IF(ISBLANK(B63),"",90)
F64: =IF(ISBLANK(B64),"",((540*26-E64)/D64)) | G64: =IF(ISBLANK(B64),"",(E64/D64)) | I64: =IF(ISBLANK(B64),"",90)
F65: =IF(ISBLANK(B65),"",((540*26-E65)/D65)) | G65: =IF(ISBLANK(B65),"",(E65/D65)) | I65: =IF(ISBLANK(B65),"",90)
F66: =IF(ISBLANK(B65),"",((540*26-E66)/D66)) | G66: =IF(ISBLANK(B66),"",(E66/D66)) | I66: =IF(ISBLANK(B66),"",90)
F67: =IF(ISBLANK(B66),"",((540*26-E67)/D67)) | G67: =IF(ISBLANK(B67),"",(E67/D67)) | I67: =IF(ISBLANK(B67),"",90)
F68: =IF(ISBLANK(B67),"",((540*26-E68)/D68)) | G68: =IF(ISBLANK(B68),"",(E68/D68))
F69: =IF(ISBLANK(B68),"",((540*26-E69)/D69))
F70: =IF(ISBLANK(B69),"",((540*26-E70)/D70))
F71: =IF(ISBLANK(B70),"",((540*26-E71)/D71))
F72: =IF(ISBLANK(B71),"",((540*26-E72)/D72))
F73: =IF(ISBLANK(B72),"",((540*26-E73)/D73))
C139: Engins roulants
A140: CODE Véhicule | B140: Marque | C140: ∑ temps d'arrêts | D140: Nb d'arrêt | E140: MTBF | F140: MTTR | G140: Disponibilité | H140: Objectif
...

Sheet En cours
A1: An | B1: (Tous)
A2: Date fin d'intervention | B2: (vide)
A4: Étiquettes de lignes | B4: Code | C4: Véhicule | D4: Détail Intervention | E4: Observations / Avancement
A5: 43878 | B5: 406 | C5: VOLVO | D5: changement d | E5: (vide)
A6: 43883 | B6: 427 | C6: Linde H30 | D6: changement du kit réparation d'axe pivot et axe fusée coté gauche et droit changemnt du kit réparation du verin de levage et inclinaison et verin de direction kit de distributeur d'accelerateur des goujon de roue arriere peinture generale d'engin vidange d'huile moteur et changement des filtres a huile moteur et filtre a gasoil | E6: (vide)
A7: 43853 | B7: 426 | C7: Manitou MC 30 | D7: en cour | E7: (vide)
A8: 43934 | B8: 481 | C8: VOLVO | D8: reparation d'eclairage | E8: (vide)
A9: 43970 | B9: 410 | C9: MAN | D9: changement du cope conique complet et deux demi arbre et deux pignon du demi arbre changement d'appareille d'air lavage et graissage generale d'engin vidange d'huile moteur 599710 km | E9: (vide)
B10: 431 | C10: Manitou M26-2 | D10: vidange d'huile moteur 15W40 | E10: (vide)
A11: 43994 | B11: 430 | C11: Fenwick H40 | D11: mise a niveau d'huile hydraulique | E11: (vide)
A12: 44001 | B12: 429 | C12: Fenwick HD30 | D12: changement du kit réparation d'axe fusee | E12: (vide)
A13: 44007 | B13: 403 | C13: MAN | D13: changement d'essieu avant achat du laferaille changement d'alternateur de charge battrie vidange d'huile moteur et changement du filtre a huile | E13: (vide)
A14: 44026 | B14: 421 | C14: Linde H30 | D14: changement du manette de llevier hydraulique | E14: (vide)
A15: 44029 | B15: 435 | C15: Mitsubishi | D15: (vide) | E15: (vide)
A16: 44041 | B16: 433 | C16: Berlingo | D16: vidange d'uhuile moteur et changement du filtre a huile et filtre du climatiseur | E16: (vide)
A17: 44081 | B17: 422 | C17: Fenwick LINDE 25 | D17: changement d'arrét d'huile pompe hydraulique des roullement de pompe et leur joint torique filtre a gasoil | E17: (vide)
A18: 44120 | B18: 417 | C18: Berlingo | D18: changement du radiateur cable d'embrayage courroie courroie d'alternateur moteur tharmique achat bon occasion fourchette d'embrayage et butée d'embrayage et arrét d'huile cardon vidange d'huile moteur km | E18: (vide)
A19: 44131 | B19: 479 | C19: Hyundai County | D19: vidange d'huile moteur 15W40 | E19: (vide)
A20: 44132 | B20: 413 | C20: Caterpillar | D20: mise a niveau d'huile hydraulique AW68 | E20: (vide)
A21: 44144 | B21: 435 | C21: Mitsubishi | D21: vidange d'huile moteur 15W40 vidange du boite de vitesse vidange d'huile du pont arriere 457450 km | E21: (vide)
A22: 44145 | B22: 429 | C22: Fenwick HD30 | D22: vidange d'huile moteur et changement du filtre a air lavage et graissage generale d'engin 7619 h | E22: (vide)
B23: 430 | C23: Fenwick H40 | D23: Vidange d'huile moteur 15W40 changement du filtre a huile et filtre a gasoil lavage et netoyyage generale d'engin 224466 km | E23: (vide)
A24: 44146 | B24: 481 | C24: VOLVO | D24: réparation d'eclairage | E24: (vide)
A25: 44165 | B25: 471 | C25: Hyundai County | D25: vidange d'huile moteur et changement du filtre a huile 2631145010 filtre a air 281304H002 filtre a gasoil3194541002 102404 km | E25: (vide)
A26: 44183 | B26: 472 | C26: Linde H25d | D26: vidange d'huile moteur 15W40 changement du filtre a huile , filtre a airet filtre a gasoil lavage et graissage generale d'engin 1946 h | E26: (vide)
A27: 44248 | B27: 434 | C27: Linde H30D | D27: changement d'afficheur | E27: (vide)
A28: 44288 | B28: 405 | C28: ISUZU | D28: répataion d'embrayage et changement du disque d'embrayage et plateau de serrage et butée réparation du problememe de charge battrie et changement d'alternateur de charge battrie changement du mecanisme de frein de stationnement | E28: (vide)
A29: 44281 | B29: 429 | C29: Fenwick HD30 | D29: réparation du distributeur hydraulique de levage des verin | E29: (vide)
A30: 44293 | B30: 431 | C30: #REF! | D30: réparation du fuite de gazoil et changement du pompe d'alimentation gazoil et des galet de rampe 8 galet | E30: (vide)
A31: 44296 | B31: 436 | C31: Mitsubishi | D31: réparation du fuite d'eau et débouchage du radiateur et reinssage du circuit de refroidissement réparation du pompe de gazoil changemnt du pompe d'amorssage gazoil changement des durite d'eau et d'huile moteur vidange d'huuiile moteur 600764 km | E31: (vide)
A32: 44300 | B32: 438 | C32: VOLVO | D32: réparation du probleme de frein moteur | E32: (vide)
A33: 44305 | B33: 426 | C33: Manitou MC 30 | D33: réparationb et débouchage du rasdiatreur peinture generale d'engin | E33: (vide)
A34: 44424 | B34: 436 | C34: Mitsubishi | D34: réparation d'eclaiare et changement des lampes vidange d'huile moteur 15W40 lavage et graissage generale d'engin mise a niveau d'huile de frein 642000 | E34: 90
A35: 44431 | B35: 438 | C35: VOLVO | D35: vidange d'huile moteur et lavage et graissage generale d'engin 305471 km | E35: (vide)
A36: 44435 | B36: 439 | C36: VOLVO | D36: réparation du fixation du rous arriere droit pour plateau et changemebnt des roullement | E36: (vide)
A37: 44481 | B37: 439 | C37: VOLVO | D37: réparation d'eclairage | E37: (vide)
